Workbook

Sheet 지급확인서
A1: 돌봄·방과후학교 강사료 지급확인서 | E1: 인건비 지급비율 | F1: 0.8
A2: 계약명 | B2: =지급내역서!B2 -> ○○초등학교 20○○학년도 돌봄·방과후학교 ○○ 프로그램 운영 위탁용역
A3: 기초자료(낙찰금액란에 낙찰금액과 계약금액이 틀린 경우 계약금액 입력)
A4: 기초금액 | B4: 130000000 | C4: 낙찰금액 (계약금액) | D4: 117000000 | E4: 기초금액대비 낙찰율 (낙찰금액/기초금액) | F4: =D4/B4 -> 0.9
A5: 지급내역현황(매월 강사료 지급 증빙자료 별도 제출)
A6: 월별 | B6: 업체 강사료 청구금액 | C6: 월별인건비지급 기준 기초금액 (청구금액/기초금액대비낙찰율) | D6: 월별 지급율 반영 인건비 금액 (월별 인건비지급기준 기초금액*인건비지급비율) | E6: 강사료지급액 (공제전금액) | F6: 인건비 지급율 (강사료지급액/월별 인건비지급기준 기초금액)
A7: 3 | B7: 8700000 | C7: =B7/$F$4 -> 9666666.7 | D7: =C7*$F$1 -> 7733333.3 | E7: =지급내역서!D8 -> 7800000 | F7: =E7/C7 -> 0.80689655
A8: 4 | B8: 7900000 | C8: =B8/$F$4 -> 8777777.8 | D8: =C8*$F$1 -> 7022222.2 | E8: =지급내역서!D13 -> 7360000 | F8: =E8/C8 -> 0.83848101
A9: 5 | B9: 8000000 | C9: =B9/$F$4 -> 8888888.9 | D9: =C9*$F$1 -> 7111111.1 | E9: =지급내역서!D18 -> 7360000 | F9: =E9/C9 -> 0.828
A10: 6 | B10: 8000000 | C10: =B10/$F$4 -> 8888888.9 | D10: =C10*$F$1 -> 7111111.1 | E10: =지급내역서!D23 -> 7360000 | F10: =E10/C10 -> 0.828
A11: 7 | C11: =B11/$F$4 -> 0 | D11: =C11*$F$1 -> 0 | F11: =E11/C11 -> #DIV/0!
A12: 8 | C12: =B12/$F$4 -> 0 | D12: =C12*$F$1 -> 0 | E12: =지급내역서!D33 -> 0 | F12: =E12/C12 -> #DIV/0!
A13: 9 | C13: =B13/$F$4 -> 0 | D13: =C13*$F$1 -> 0 | E13: =지급내역서!D38 -> 0 | F13: =E13/C13 -> #DIV/0!
A14: 10 | C14: =B14/$F$4 -> 0 | D14: =C14*$F$1 -> 0 | E14: =지급내역서!D43 -> 0 | F14: =E14/C14 -> #DIV/0!
A15: 11 | C15: =B15/$F$4 -> 0 | D15: =C15*$F$1 -> 0 | E15: =지급내역서!D48 -> 0 | F15: =E15/C15 -> #DIV/0!
A16: 12 | C16: =B16/$F$4 -> 0 | D16: =C16*$F$1 -> 0 | E16: =지급내역서!D53 -> 0 | F16: =E16/C16 -> #DIV/0!
A17: 13 | C17: =B17/$F$4 -> 0 | D17: =C17*$F$1 -> 0 | E17: =지급내역서!D58 -> 0 | F17: =E17/C17 -> #DIV/0!
A18: 14 | C18: =B18/$F$4 -> 0 | D18: =C18*$F$1 -> 0 | E18: =지급내역서!D63 -> 0 | F18: =E18/C18 -> #DIV/0!
A19: 합계(누계) | B19: =SUM(B7:B18) -> 32600000 | C19: =SUM(C7:C18) -> 36222222 | D19: =SUM(D7:D18) -> 28977778 | E19: =SUM(E7:E18) -> 29880000 | F19: =E19/C19 -> 0.82490798
A21: 작 성 자 | B21: 업체명 | E21: 사업자등록번호
B22: 대표자 | D22: (인) | E22: 전화번호
A23: 확인자 | B23: 소속
B24: 직위(직급)
B25: 성명 | D25: (서명)

Sheet 지급내역서
A1: 월별 돌봄·방과후학교 강사료 지급내역서
A2: 계약건명 | B2: ○○초등학교 20○○학년도 돌봄·방과후학교 ○○ 프로그램 운영 위탁용역
A3: 월 | B3: 과목명 | C3: 강사명 | D3: 강사료금액 | E3: 공제액 | F3: 실지급액 | G3: 인건비지급일
A4: 3 | F4: =ROUND(D4-E4,-1) -> 0
F5: =ROUND(D5-E5,-1) -> 0
F6: =ROUND(D6-E6,-1) -> 0
D7: 7800000 | E7: =D7*3.3%+D7*0.7% -> 312000 | F7: =ROUND(D7-E7,-1) -> 7488000
B8: 소계 | D8: =SUM(D4:D7) -> 7800000 | E8: =SUM(E4:E7) -> 312000 | F8: =SUM(F4:F7) -> 7488000
A9: 4 | F9: =ROUND(D9-E9,-1) -> 0
F10: =ROUND(D10-E10,-1) -> 0
F11: =ROUND(D11-E11,-1) -> 0
D12: 7360000 | E12: 70000 | F12: =ROUND(D12-E12,-1) -> 7290000
B13: 소계 | D13: =SUM(D9:D12) -> 7360000 | E13: =SUM(E9:E12) -> 70000 | F13: =SUM(F9:F12) -> 7290000
A14: 5 | F14: =ROUND(D14-E14,-1) -> 0
F15: =ROUND(D15-E15,-1) -> 0
F16: =ROUND(D16-E16,-1) -> 0
D17: 7360000 | F17: =ROUND(D17-E17,-1) -> 7360000
B18: 소계 | D18: =SUM(D14:D17) -> 7360000 | E18: =SUM(E14:E17) -> 0 | F18: =SUM(F14:F17) -> 7360000
A19: 6 | F19: =ROUND(D19-E19,-1) -> 0
F20: =ROUND(D20-E20,-1) -> 0
F21: =ROUND(D21-E21,-1) -> 0
D22: 7360000 | F22: =ROUND(D22-E22,-1) -> 7360000
B23: 소계 | D23: =SUM(D19:D22) -> 7360000 | E23: =SUM(E19:E22) -> 0 | F23: =SUM(F19:F22) -> 7360000
A24: 7 | F24: =ROUND(D24-E24,-1) -> 0
F25: =ROUND(D25-E25,-1) -> 0
F26: =ROUND(D26-E26,-1) -> 0
F27: =ROUND(D27-E27,-1) -> 0
B28: 소계 | D28: =SUM(D24:D27) -> 0 | E28: =SUM(E24:E27) -> 0 | F28: =SUM(F24:F27) -> 0
A29: 8 | F29: =ROUND(D29-E29,-1) -> 0
F30: =ROUND(D30-E30,-1) -> 0
F31: =ROUND(D31-E31,-1) -> 0
F32: =ROUND(D32-E32,-1) -> 0
B33: 소계 | D33: =SUM(D29:D32) -> 0 | E33: =SUM(E29:E32) -> 0 | F33: =SUM(F29:F32) -> 0
A34: 9 | F34: =ROUND(D34-E34,-1) -> 0
F35: =ROUND(D35-E35,-1) -> 0
F36: =ROUND(D36-E36,-1) -> 0
F37: =ROUND(D37-E37,-1) -> 0
B38: 소계 | D38: =SUM(D34:D37) -> 0 | E38: =SUM(E34:E37) -> 0 | F38: =SUM(F34:F37) -> 0
A39: 10 | F39: =ROUND(D39-E39,-1) -> 0
F40: =ROUND(D40-E40,-1) -> 0
...
